[2023-11-03T01:56:59.212+0000] {taskinstance.py:1159} INFO - Dependencies all met for dep_context=non-requeueable deps ti=<TaskInstance: recalls_etl_v1.get_raw_data manual__2023-11-03T01:56:56.189529+00:00 [queued]>
[2023-11-03T01:56:59.226+0000] {taskinstance.py:1159} INFO - Dependencies all met for dep_context=requeueable deps ti=<TaskInstance: recalls_etl_v1.get_raw_data manual__2023-11-03T01:56:56.189529+00:00 [queued]>
[2023-11-03T01:56:59.226+0000] {taskinstance.py:1361} INFO - Starting attempt 1 of 1
[2023-11-03T01:56:59.251+0000] {taskinstance.py:1382} INFO - Executing <Task(PythonOperator): get_raw_data> on 2023-11-03 01:56:56.189529+00:00
[2023-11-03T01:56:59.259+0000] {standard_task_runner.py:57} INFO - Started process 515 to run task
[2023-11-03T01:56:59.265+0000] {standard_task_runner.py:84} INFO - Running: ['***', 'tasks', 'run', 'recalls_etl_v1', 'get_raw_data', 'manual__2023-11-03T01:56:56.189529+00:00', '--job-id', '6', '--raw', '--subdir', 'DAGS_FOLDER/recalls_etl_v1.py', '--cfg-path', '/tmp/tmpa7z_sszd']
[2023-11-03T01:56:59.266+0000] {standard_task_runner.py:85} INFO - Job 6: Subtask get_raw_data
[2023-11-03T01:56:59.333+0000] {task_command.py:416} INFO - Running <TaskInstance: recalls_etl_v1.get_raw_data manual__2023-11-03T01:56:56.189529+00:00 [running]> on host 4f62393bc3c9
[2023-11-03T01:56:59.440+0000] {taskinstance.py:1662} INFO - Exporting env vars: AIRFLOW_CTX_DAG_OWNER='***' AIRFLOW_CTX_DAG_ID='recalls_etl_v1' AIRFLOW_CTX_TASK_ID='get_raw_data' AIRFLOW_CTX_EXECUTION_DATE='2023-11-03T01:56:56.189529+00:00' AIRFLOW_CTX_TRY_NUMBER='1' AIRFLOW_CTX_DAG_RUN_ID='manual__2023-11-03T01:56:56.189529+00:00'
[2023-11-03T01:57:00.434+0000] {logging_mixin.py:151} INFO - <Response [200]>
[2023-11-03T01:57:00.434+0000] {taskinstance.py:1937} ERROR - Task failed with exception
Traceback (most recent call last):
  File "/home/airflow/.local/lib/python3.8/site-packages/airflow/operators/python.py", line 192, in execute
    return_value = self.execute_callable()
  File "/home/airflow/.local/lib/python3.8/site-packages/airflow/operators/python.py", line 209, in execute_callable
    return self.python_callable(*self.op_args, **self.op_kwargs)
  File "/opt/airflow/dags/recalls_etl_v1.py", line 35, in get_recall_data
    recall_list
NameError: name 'recall_list' is not defined
[2023-11-03T01:57:00.445+0000] {taskinstance.py:1400} INFO - Marking task as FAILED. dag_id=recalls_etl_v1, task_id=get_raw_data, execution_date=20231103T015656, start_date=20231103T015659, end_date=20231103T015700
[2023-11-03T01:57:00.463+0000] {standard_task_runner.py:104} ERROR - Failed to execute job 6 for task get_raw_data (name 'recall_list' is not defined; 515)
[2023-11-03T01:57:00.484+0000] {local_task_job_runner.py:228} INFO - Task exited with return code 1
[2023-11-03T01:57:00.516+0000] {taskinstance.py:2778} INFO - 0 downstream tasks scheduled from follow-on schedule check
