[2023-11-03T01:59:14.160+0000] {taskinstance.py:1159} INFO - Dependencies all met for dep_context=non-requeueable deps ti=<TaskInstance: recalls_etl_v1.get_raw_data manual__2023-11-03T01:59:12.098052+00:00 [queued]>
[2023-11-03T01:59:14.172+0000] {taskinstance.py:1159} INFO - Dependencies all met for dep_context=requeueable deps ti=<TaskInstance: recalls_etl_v1.get_raw_data manual__2023-11-03T01:59:12.098052+00:00 [queued]>
[2023-11-03T01:59:14.172+0000] {taskinstance.py:1361} INFO - Starting attempt 1 of 1
[2023-11-03T01:59:14.194+0000] {taskinstance.py:1382} INFO - Executing <Task(PythonOperator): get_raw_data> on 2023-11-03 01:59:12.098052+00:00
[2023-11-03T01:59:14.200+0000] {standard_task_runner.py:57} INFO - Started process 554 to run task
[2023-11-03T01:59:14.204+0000] {standard_task_runner.py:84} INFO - Running: ['***', 'tasks', 'run', 'recalls_etl_v1', 'get_raw_data', 'manual__2023-11-03T01:59:12.098052+00:00', '--job-id', '8', '--raw', '--subdir', 'DAGS_FOLDER/recalls_etl_v1.py', '--cfg-path', '/tmp/tmp8001x8u_']
[2023-11-03T01:59:14.206+0000] {standard_task_runner.py:85} INFO - Job 8: Subtask get_raw_data
[2023-11-03T01:59:14.280+0000] {task_command.py:416} INFO - Running <TaskInstance: recalls_etl_v1.get_raw_data manual__2023-11-03T01:59:12.098052+00:00 [running]> on host 4f62393bc3c9
[2023-11-03T01:59:14.481+0000] {taskinstance.py:1662} INFO - Exporting env vars: AIRFLOW_CTX_DAG_OWNER='***' AIRFLOW_CTX_DAG_ID='recalls_etl_v1' AIRFLOW_CTX_TASK_ID='get_raw_data' AIRFLOW_CTX_EXECUTION_DATE='2023-11-03T01:59:12.098052+00:00' AIRFLOW_CTX_TRY_NUMBER='1' AIRFLOW_CTX_DAG_RUN_ID='manual__2023-11-03T01:59:12.098052+00:00'
[2023-11-03T01:59:15.438+0000] {logging_mixin.py:151} INFO - <Response [200]>
[2023-11-03T01:59:15.460+0000] {logging_mixin.py:151} INFO - Added 29177 recalled records.
[2023-11-03T01:59:15.503+0000] {taskinstance.py:1937} ERROR - Task failed with exception
Traceback (most recent call last):
  File "/home/airflow/.local/lib/python3.8/site-packages/airflow/operators/python.py", line 192, in execute
    return_value = self.execute_callable()
  File "/home/airflow/.local/lib/python3.8/site-packages/airflow/operators/python.py", line 209, in execute_callable
    return self.python_callable(*self.op_args, **self.op_kwargs)
  File "/opt/airflow/dags/recalls_etl_v1.py", line 57, in get_recall_data
    recall_df.to_csv(raw_output_path, index=False)
  File "/home/airflow/.local/lib/python3.8/site-packages/pandas/core/generic.py", line 3772, in to_csv
    return DataFrameRenderer(formatter).to_csv(
  File "/home/airflow/.local/lib/python3.8/site-packages/pandas/io/formats/format.py", line 1186, in to_csv
    csv_formatter.save()
  File "/home/airflow/.local/lib/python3.8/site-packages/pandas/io/formats/csvs.py", line 240, in save
    with get_handle(
  File "/home/airflow/.local/lib/python3.8/site-packages/pandas/io/common.py", line 737, in get_handle
    check_parent_directory(str(handle))
  File "/home/airflow/.local/lib/python3.8/site-packages/pandas/io/common.py", line 600, in check_parent_directory
    raise OSError(rf"Cannot save file into a non-existent directory: '{parent}'")
OSError: Cannot save file into a non-existent directory: '../data/raw'
[2023-11-03T01:59:15.515+0000] {taskinstance.py:1400} INFO - Marking task as FAILED. dag_id=recalls_etl_v1, task_id=get_raw_data, execution_date=20231103T015912, start_date=20231103T015914, end_date=20231103T015915
[2023-11-03T01:59:15.531+0000] {standard_task_runner.py:104} ERROR - Failed to execute job 8 for task get_raw_data (Cannot save file into a non-existent directory: '../data/raw'; 554)
[2023-11-03T01:59:15.551+0000] {local_task_job_runner.py:228} INFO - Task exited with return code 1
[2023-11-03T01:59:15.579+0000] {taskinstance.py:2778} INFO - 0 downstream tasks scheduled from follow-on schedule check
