[2023-11-08T02:32:48.599+0000] {taskinstance.py:1159} INFO - Dependencies all met for dep_context=non-requeueable deps ti=<TaskInstance: recalls_etl_v2.get_raw_data manual__2023-11-08T02:32:46.547028+00:00 [queued]>
[2023-11-08T02:32:48.615+0000] {taskinstance.py:1159} INFO - Dependencies all met for dep_context=requeueable deps ti=<TaskInstance: recalls_etl_v2.get_raw_data manual__2023-11-08T02:32:46.547028+00:00 [queued]>
[2023-11-08T02:32:48.615+0000] {taskinstance.py:1361} INFO - Starting attempt 1 of 1
[2023-11-08T02:32:48.670+0000] {taskinstance.py:1382} INFO - Executing <Task(PythonOperator): get_raw_data> on 2023-11-08 02:32:46.547028+00:00
[2023-11-08T02:32:48.683+0000] {standard_task_runner.py:57} INFO - Started process 467 to run task
[2023-11-08T02:32:48.690+0000] {standard_task_runner.py:84} INFO - Running: ['***', 'tasks', 'run', 'recalls_etl_v2', 'get_raw_data', 'manual__2023-11-08T02:32:46.547028+00:00', '--job-id', '29', '--raw', '--subdir', 'DAGS_FOLDER/recalls_etl_v2.py', '--cfg-path', '/tmp/tmp9jncec21']
[2023-11-08T02:32:48.695+0000] {standard_task_runner.py:85} INFO - Job 29: Subtask get_raw_data
[2023-11-08T02:32:48.842+0000] {task_command.py:416} INFO - Running <TaskInstance: recalls_etl_v2.get_raw_data manual__2023-11-08T02:32:46.547028+00:00 [running]> on host d2f41c2a3488
[2023-11-08T02:32:49.039+0000] {taskinstance.py:1662} INFO - Exporting env vars: AIRFLOW_CTX_DAG_OWNER='***' AIRFLOW_CTX_DAG_ID='recalls_etl_v2' AIRFLOW_CTX_TASK_ID='get_raw_data' AIRFLOW_CTX_EXECUTION_DATE='2023-11-08T02:32:46.547028+00:00' AIRFLOW_CTX_TRY_NUMBER='1' AIRFLOW_CTX_DAG_RUN_ID='manual__2023-11-08T02:32:46.547028+00:00'
[2023-11-08T02:35:01.476+0000] {taskinstance.py:1937} ERROR - Task failed with exception
Traceback (most recent call last):
  File "/home/airflow/.local/lib/python3.8/site-packages/requests/models.py", line 971, in json
    return complexjson.loads(self.text, **kwargs)
  File "/usr/local/lib/python3.8/json/__init__.py", line 357, in loads
    return _default_decoder.decode(s)
  File "/usr/local/lib/python3.8/json/decoder.py", line 337, in decode
    obj, end = self.raw_decode(s, idx=_w(s, 0).end())
  File "/usr/local/lib/python3.8/json/decoder.py", line 355, in raw_decode
    raise JSONDecodeError("Expecting value", s, err.value) from None
json.decoder.JSONDecodeError: Expecting value: line 1 column 13107201 (char 13107200)

During handling of the above exception, another exception occurred:

Traceback (most recent call last):
  File "/home/airflow/.local/lib/python3.8/site-packages/airflow/operators/python.py", line 192, in execute
    return_value = self.execute_callable()
  File "/home/airflow/.local/lib/python3.8/site-packages/airflow/operators/python.py", line 209, in execute_callable
    return self.python_callable(*self.op_args, **self.op_kwargs)
  File "/opt/airflow/dags/recalls_etl_v2.py", line 31, in get_recall_data
    response_data = response.json()
  File "/home/airflow/.local/lib/python3.8/site-packages/requests/models.py", line 975, in json
    raise RequestsJSONDecodeError(e.msg, e.doc, e.pos)
requests.exceptions.JSONDecodeError: Expecting value: line 1 column 13107201 (char 13107200)
[2023-11-08T02:35:01.487+0000] {taskinstance.py:1400} INFO - Marking task as FAILED. dag_id=recalls_etl_v2, task_id=get_raw_data, execution_date=20231108T023246, start_date=20231108T023248, end_date=20231108T023501
[2023-11-08T02:35:01.503+0000] {standard_task_runner.py:104} ERROR - Failed to execute job 29 for task get_raw_data (Expecting value: line 1 column 13107201 (char 13107200); 467)
[2023-11-08T02:35:01.519+0000] {local_task_job_runner.py:228} INFO - Task exited with return code 1
[2023-11-08T02:35:01.548+0000] {taskinstance.py:2778} INFO - 0 downstream tasks scheduled from follow-on schedule check
